<mujoco model="quadrotor0">
	<compiler inertiafromgeom="true" coordinate="local"/>
	<option	timestep="0.001" gravity="0 0 -9.81" density="1" viscosity="1e-5" />
	<worldbody>
		<geom name="floor" pos="0 0 0" size="2 2 .2" type="plane"  conaffinity="1" rgba="1 1 1 1" condim="3"/>
		<body name="quadrotor" pos="0 0 1.0">
			<joint name="root"   type="free" damping="0" armature="0" pos="0 0 0" />

			<!-- Actuator sites to attach actuators, make it invisible -->
            <site name="thrust" type="box" pos="0 0 0"  size="0.035 0.035 0.035"  quat = "1.0 0.0 0.0 0." rgba="0 1 1 0" />
            <geom name="thruster0" type="cylinder" pos="0 0 0" size="0.05 0.2"  quat = "1.0 0.0 0.0 0." rgba="1 0.0 0.0 1" mass = "1"/>

            <!-- Visualization of the coordinate frame -->
			<site name="qcX" type="box" pos="0.1 0.0 0.0" size="0.1 0.005 0.005"  quat = " 1.000  0.0  0.0    0."     rgba="1 0 0 1" />
			<site name="qcY" type="box" pos="0.0 0.1 0.0" size="0.1 0.005 0.005"  quat = " 0.707  0.0  0.0    0.707"  rgba="0 1 0 1" />
			<site name="qcZ" type="box" pos="0.0 0.0 0.2" size="0.2 0.005 0.005"  quat = "-0.707  0.0  0.707  0."     rgba="0 0 1 1" />

			<body name="cart" pos="0 0 0">
				<joint axis="1 0 0" limited="true" name="slider" pos="0 0 0" range="-0.25 0.25" type="slide"/>
				<geom name="cart" pos="0 0 0" quat="0.707 0 0.707 0" size="0.08" type="sphere" mass = "0.01"/>
			</body>
		</body>
	</worldbody>
    <actuator>
		<motor ctrllimited="true" ctrlrange="0.0 20.0" gear="0  0. 1. 0. 0. 0." site="thrust"/>
		<motor ctrllimited="true" ctrlrange="-1.0 1.0" gear="0.5" joint="slider" name="slide"/>
	</actuator>
</mujoco>